<?xml version="1.0" ?>
<!-- =================================================================================== -->
<!-- |    This document was autogenerated by xacro from model.xacro                    | -->
<!-- |    EDITING THIS FILE BY HAND IS NOT RECOMMENDED                                 | -->
<!-- =================================================================================== -->
<robot name="tether">
  <link name="element_5">
    <inertial>
      <origin rpy="0 1.5707963267948966 0" xyz="0.3 0 0"/>
      <mass value="0.02"/>
      <inertia ixx="0.0006005" ixy="0" ixz="0" iyy="0.0006005" iyz="0" izz="1.0000000000000002e-06"/>
    </inertial>
    <visual>
      <origin rpy="0 1.5707963267948966 0" xyz="0.3 0 0"/>
      <geometry>
        <cylinder length="0.6" radius="0.01"/>
      </geometry>
    </visual>
    <collision>
      <origin rpy="0 1.5707963267948966 0" xyz="0.3 0 0"/>
      <geometry>
        <cylinder length="0.6" radius="0.01"/>
      </geometry>
    </collision>
  </link>
  <link name="element_4">
    <inertial>
      <origin rpy="0 1.5707963267948966 0" xyz="0.3 0 0"/>
      <mass value="0.02"/>
      <inertia ixx="0.0006005" ixy="0" ixz="0" iyy="0.0006005" iyz="0" izz="1.0000000000000002e-06"/>
    </inertial>
    <visual>
      <origin rpy="0 1.5707963267948966 0" xyz="0.3 0 0"/>
      <geometry>
        <cylinder length="0.6" radius="0.01"/>
      </geometry>
    </visual>
    <collision>
      <origin rpy="0 1.5707963267948966 0" xyz="0.3 0 0"/>
      <geometry>
        <cylinder length="0.6" radius="0.01"/>
      </geometry>
    </collision>
  </link>
  <link name="element_3">
    <inertial>
      <origin rpy="0 1.5707963267948966 0" xyz="0.3 0 0"/>
      <mass value="0.02"/>
      <inertia ixx="0.0006005" ixy="0" ixz="0" iyy="0.0006005" iyz="0" izz="1.0000000000000002e-06"/>
    </inertial>
    <visual>
      <origin rpy="0 1.5707963267948966 0" xyz="0.3 0 0"/>
      <geometry>
        <cylinder length="0.6" radius="0.01"/>
      </geometry>
    </visual>
    <collision>
      <origin rpy="0 1.5707963267948966 0" xyz="0.3 0 0"/>
      <geometry>
        <cylinder length="0.6" radius="0.01"/>
      </geometry>
    </collision>
  </link>
  <link name="element_2">
    <inertial>
      <origin rpy="0 1.5707963267948966 0" xyz="0.3 0 0"/>
      <mass value="0.02"/>
      <inertia ixx="0.0006005" ixy="0" ixz="0" iyy="0.0006005" iyz="0" izz="1.0000000000000002e-06"/>
    </inertial>
    <visual>
      <origin rpy="0 1.5707963267948966 0" xyz="0.3 0 0"/>
      <geometry>
        <cylinder length="0.6" radius="0.01"/>
      </geometry>
    </visual>
    <collision>
      <origin rpy="0 1.5707963267948966 0" xyz="0.3 0 0"/>
      <geometry>
        <cylinder length="0.6" radius="0.01"/>
      </geometry>
    </collision>
  </link>
  <link name="element_1">
    <inertial>
      <origin rpy="0 1.5707963267948966 0" xyz="0.3 0 0"/>
      <mass value="0.02"/>
      <inertia ixx="0.0006005" ixy="0" ixz="0" iyy="0.0006005" iyz="0" izz="1.0000000000000002e-06"/>
    </inertial>
    <visual>
      <origin rpy="0 1.5707963267948966 0" xyz="0.3 0 0"/>
      <geometry>
        <cylinder length="0.6" radius="0.01"/>
      </geometry>
    </visual>
    <collision>
      <origin rpy="0 1.5707963267948966 0" xyz="0.3 0 0"/>
      <geometry>
        <cylinder length="0.6" radius="0.01"/>
      </geometry>
    </collision>
  </link>
  <joint name="joint_1_to_2" type="continuous">
    <axis xyz="0. 0. 1."/>
    <origin rpy="0 0 0" xyz="0.6 0 0"/>
    <parent link="element_1"/>
    <child link="element_2"/>
  </joint>
  <joint name="joint_2_to_3" type="continuous">
    <axis xyz="0. 0. 1."/>
    <origin rpy="0 0 0" xyz="0.6 0 0"/>
    <parent link="element_2"/>
    <child link="element_3"/>
  </joint>
  <joint name="joint_3_to_4" type="continuous">
    <axis xyz="0. 0. 1."/>
    <origin rpy="0 0 0" xyz="0.6 0 0"/>
    <parent link="element_3"/>
    <child link="element_4"/>
  </joint>
  <joint name="joint_4_to_5" type="continuous">
    <axis xyz="0. 0. 1."/>
    <origin rpy="0 0 0" xyz="0.6 0 0"/>
    <parent link="element_4"/>
    <child link="element_5"/>
  </joint>
</robot>
